<?xml version="1.0" ?>
<robot name="uav_sensors" xmlns:xacro="http://ros.org/wiki/xacro">

  <!-- Init colour -->
  <material name="black">
      <color rgba="0.0 0.0 0.0 1.0"/>
  </material>

  <material name="dark">
    <color rgba="0.3 0.3 0.3 1.0"/>
  </material>

  <material name="light_black">
    <color rgba="0.4 0.4 0.4 1.0"/>
  </material>

  <material name="blue">
    <color rgba="0.0 0.0 0.8 1.0"/>
  </material>

  <material name="green">
    <color rgba="0.0 0.8 0.0 1.0"/>
  </material>

  <material name="grey">
    <color rgba="0.5 0.5 0.5 1.0"/>
  </material>

  <material name="orange">
    <color rgba="1.0 0.4235 0.0392 1.0"/>
  </material>

  <material name="brown">
    <color rgba="0.8706 0.8118 0.7647 1.0"/>
  </material>

  <material name="red">
    <color rgba="0.8 0.0 0.0 1.0"/>
  </material>

  <material name="white">
    <color rgba="1.0 1.0 1.0 1.0"/>
  </material>


  <!--Main build-->
  <link name="base_footprint"/>

  <joint name="base_joint" type="fixed">
    <parent link="base_footprint"/>
    <child link="base_link"/>
    <origin xyz="0.0 0.0 0.0" rpy="0 0 0"/>
  </joint>

  <link name='base_link'>
    <visual name='base_link_visual'>
        <origin xyz="0 0 0.194923" rpy="0 0 0"/>
        <geometry>
            <mesh filename="package://uav_gazebo/models/iris_sensors/meshes/iris.dae" scale="1 1 1"/>
        </geometry>
        <material name="light_black"/>
    </visual>

    <collision name='base_link_collision'>
        <origin xyz="0 0 0.10" rpy="0 0 0"/>
        <geometry>
            <box size="0.47 0.47 0.23"/>
        </geometry>
        <surface>
            <contact>
            <ode>
                <max_vel>100.0</max_vel>
                <min_depth>0.001</min_depth>
            </ode>
            </contact>
            <friction>
            <ode>
                <mu>100000.0</mu>
                <mu2>100000.0</mu2>
            </ode>
            </friction>
        </surface>
    </collision>

    <inertial>
        <origin xyz="0 0 0" rpy="0 0 0"/>
        <mass value="1.5"/>
        <inertia ixx="8e-03" ixy="0" ixz="0" iyy="1.5e-2" iyz="0" izz="1.7e-2" />
    </inertial>

    <visual name='front_left_leg_visual'>
        <origin xyz="0.123 0.22 0.10" rpy="0 0 0"/>
        <geometry>
            <cylinder radius="0.005" length="0.17" />
        </geometry>
        <material name="light_black"/>
    </visual>

    <visual name='front_right_leg_visual'>
        <origin xyz="0.123 -0.22 0.10" rpy="0 0 0"/>
        <geometry>
            <cylinder radius="0.005" length="0.17" />
        </geometry>
        <material name="light_black"/>
    </visual>

    <visual name='rear_left_leg_visual'>
        <origin xyz="-0.140 0.21 0.10" rpy="0 0 0"/>
        <geometry>
            <cylinder radius="0.005" length="0.17" />
        </geometry>
        <material name="light_black"/>
    </visual>

    <visual name='rear_right_leg_visual'>
        <origin xyz="-0.140 -0.21 0.10" rpy="0 0 0"/>
        <geometry>
            <cylinder radius="0.005" length="0.17" />
        </geometry>
        <material name="light_black"/>
    </visual>
  </link>


  <!--Sensors-->
  <!--Odometry-->
  <joint name='odom_joint' type='fixed'>
    <child link="base_footprint"/>
    <parent link="odom"/>
    <axis xyz="0 0 1"/>

    <limit effort="0" velocity="0" lower="0" upper="0"/>
    <dynamics damping="1.0"/>
    <use_parent_model_frame>1</use_parent_model_frame>
  </joint>

  <link name='odom'>
    <inertial>
      <origin xyz="0 0 0" rpy="0 -0 0"/>
      <mass value="1e-02"/>
      <inertia ixx="1e-04" ixy="0" ixz="0" iyy="2e-4" iyz="0" izz="2e-4" />
    </inertial>
  </link>


  <!--IMU-->
  <joint name='imu_joint' type='fixed'>
    <parent link="base_link"/>
    <child link="imu_link"/>
    <axis xyz="0 0 1"/>

    <limit effort="0" velocity="0" lower="0" upper="0"/>
    <dynamics damping="1.0"/>
    <use_parent_model_frame>1</use_parent_model_frame>
  </joint>

  <link name='imu_link'>
    <inertial>
      <origin xyz="0 0 0" rpy="0 0 0"/>
      <mass value="1.5e-01"/>
      <inertia ixx="1e-04" ixy="0" ixz="0" iyy="2e-04" iyz="0" izz="2e-04" />
    </inertial>
  </link>


  <!--LiDAR-->
  <joint name="hokuyo_joint" type="fixed">
    <origin xyz="0 0 0" rpy="0 0 0"/>
    <parent link="base_link"/>
    <child link="hokuyo_link"/>
  </joint>

  <link name="hokuyo_link">
    <inertial>
      <origin xyz="0 0 0" rpy="0 0 0"/>
      <mass value="1.6e-02"/>
      <inertia ixx="1e-04" ixy="0" ixz="0" iyy="1e-4" iyz="0" izz="1e-4" />
    </inertial>    

    <visual name="visual">
      <origin xyz="0 0 0.27" rpy="0 0 0" />
      <geometry>
        <mesh filename="package://uav_gazebo/models/iris_sensors/meshes/hokuyo.dae"/>
      </geometry>
    </visual>

    <collision name="collision">
      <origin xyz="0 0 0.3" rpy="0 0 0"/>
      <geometry>
        <box size="0.1 0.1 0.1" />
      </geometry>
    </collision>
  </link>


  <!--Camera-->
  <link name="camera_bottom_screw_frame">
    <visual>
      <origin xyz="0 0 0.1" rpy="0 0 0"/>
      <geometry>
        <mesh filename="package://uav_gazebo/models/iris_sensors/meshes/d435.dae" />
      </geometry>
    </visual>

    <collision>
      <origin xyz="0 0 0.1" rpy="0 0 0"/>
      <geometry>
        <mesh filename="package://uav_gazebo/models/iris_sensors/meshes/d435.dae" />
      </geometry>
    </collision>
  </link>

  <link name="camera_link"></link>

  <link name="camera_depth_frame"></link>

  <link name="camera_depth_optical_frame"></link>

  <link name="camera_color_frame"></link>

  <link name="camera_color_optical_frame"></link>

  <link name="camera_left_ir_frame"></link>

  <link name="camera_left_ir_optical_frame"></link>

  <link name="camera_right_ir_frame"></link>

  <link name="camera_right_ir_optical_frame"></link>


  <joint name="camera_joint" type="fixed">
    <parent link="base_link" />
    <child link="camera_bottom_screw_frame" />
    <pose xyz="0.4 0 0.25" rpy="0 0 0" />
  </joint>

  <joint name="camera_link_joint" type="fixed">
    <parent link="camera_bottom_screw_frame" />
    <child link="camera_link" />
    <pose xyz="0 0.0175 0.0125 " rpy="0 0 0" />
  </joint>

  <joint name="camera_depth_joint" type="fixed">
    <parent link="camera_link" />
    <child link="camera_depth_frame" />
    <pose xyz="0 0 0" rpy="0 0 0" />
  </joint>

  <joint name="camera_depth_optical_joint" type="fixed">
    <parent link="camera_depth_frame" />
    <child link="camera_depth_optical_frame" />
    <pose xyz="0 0 0 " rpy="-1.57 0 -1.57" />
  </joint>

  <joint name="camera_color_joint" type="fixed">
    <parent link="camera_depth_frame" />
    <child link="camera_color_frame" />
    <pose xyz="0 0 0" rpy="0 0 0" />
  </joint>

  <joint name="camera_color_optical_joint" type="fixed">
    <parent link="camera_color_frame" />
    <child link="camera_color_optical_frame" />
    <pose xyz="0 0 0 " rpy="-1.57 0 -1.57" />
  </joint>

  <joint name="camera_left_ir_joint" type="fixed">
    <parent link="camera_depth_frame" />
    <child link="camera_left_ir_frame" />
    <pose xyz="0 0 0 " rpy="0 0 0 " />
  </joint>

  <joint name="camera_left_ir_optical_joint" type="fixed">
    <parent link="camera_left_ir_frame" />
    <child link="camera_left_ir_optical_frame" />
    <pose xyz="0 0 0 " rpy="-1.57 0 -1.57" />
  </joint>

  <joint name="camera_right_ir_joint" type="fixed">
    <parent link="camera_depth_frame" />
    <child link="camera_right_ir_frame" />
    <pose xyz="0 -0.050 0 " rpy="0 0 0" />
  </joint>

  <joint name="camera_right_ir_optical_joint" type="fixed">
    <parent link="camera_right_ir_frame" />
    <child link="camera_right_ir_optical_frame" />
    <pose xyz="0 0 0 " rpy="-1.57 0 -1.57" />
  </joint>


<!--
    <link name='iris/imugt_link'>
      <pose>0 0 0 0 -0 0</pose>
      <inertial>
        <pose>0 0 0 0 -0 0</pose>
        <mass>1e-02</mass>
        <inertia>
          <ixx>0.0002</ixx>
          <ixy>0</ixy>
          <ixz>0</ixz>
          <iyy>0.0002</iyy>
          <iyz>0</iyz>
          <izz>0.0002</izz>
        </inertia>
      </inertial>
    </link>

    <joint name='iris/imugt_joint' type='revolute'>
      <child>iris/imugt_link</child>
      <parent>base_link</parent>
      <axis>
        <xyz>0 0 1</xyz>
        <limit>
          <lower>0</lower>
          <upper>0</upper>
          <effort>0</effort>
          <velocity>0</velocity>
        </limit>
        <dynamics>
          <spring_reference>0</spring_reference>
          <spring_stiffness>0</spring_stiffness>
        </dynamics>
        <use_parent_model_frame>1</use_parent_model_frame>
      </axis>
    </joint>
-->

  <joint name='rotor_0_joint' type='revolute'>
    <parent link="base_link"/>
    <child link="rotor_0"/>
    <axis xyz="0 0 1"/>
    <limit effort="0" velocity="0" lower="-1e+16" upper="1e+16" />
    <dynamics damping="0.004"/>
    <use_parent_model_frame>1</use_parent_model_frame>
    <!-- <physics>
      <ode>
        <implicit_spring_damper>1</implicit_spring_damper>
      </ode>
    </physics> -->
  </joint>

  <link name='rotor_0'>
    <inertial>
      <origin xyz="0 0 0" rpy="0 -0 0" />
      <mass value="0.025" />
      <inertia ixx="9.75e-06" ixy="0" ixz="0" iyy="0.000166704" iyz="0" izz="0.000167604" />
    </inertial>

    <collision name='rotor_0_collision'>
      <origin xyz="0 0 0" rpy="0 -0 0" />
      <geometry>
        <cylinder length="0.005" radius="0.1"/>
      </geometry>
      <surface contact="ode" friction="ode"/>
    </collision>

    <visual name='rotor_0_visual'>
      <origin xyz="0.13 -0.22 0.223" rpy="0 -0 0" />
      <geometry>
        <mesh filename="package://uav_gazebo/models/iris_sensors/meshes/iris_prop_ccw.dae" scale="1 1 1"/>
      </geometry>
      <material name="light_black"/>
    </visual>
    <!-- <gravity>1</gravity>
    <velocity_decay/>
    <self_collide>0</self_collide> -->
  </link>

  <joint name='rotor_1_joint' type='revolute'>
    <parent link="base_link"/>
    <child link="rotor_1"/>
    <axis xyz="0 0 1"/>
    
    <limit effort="0" velocity="0" lower="-1e+16" upper="1e+16"/>
    <dynamics damping="0.004"/>
    <use_parent_model_frame>1</use_parent_model_frame>
    <!-- <physics>
      <ode>
        <implicit_spring_damper>1</implicit_spring_damper>
      </ode>
    </physics> -->
  </joint>

  <link name='rotor_1'>
    <inertial>
      <origin xyz="0 0 0" rpy="0 -0 0"/>
      <mass value="0.025"/>
      <inertia ixx="9.75e-06" ixy="0" ixz="0" iyy="0.000166704" iyz="0" izz="0.000167604" />
    </inertial>

    <collision name='rotor_1_collision'>
      <origin xyz="0 0 0" rpy="0 -0 0"/>
      <geometry>
        <cylinder length="0.005" radius="0.1"/>
      </geometry>
      <!-- <surface>
        <contact>
          <ode/>
        </contact>
        <friction>
          <ode/>
        </friction>
      </surface> -->
    </collision>

    <visual name='rotor_1_visual'>
      <origin xyz="-0.13 0.2 0.223" rpy="0 -0 0"/>
      <geometry>
        <mesh filename="package://uav_gazebo/models/iris_sensors/meshes/iris_prop_ccw.dae" scale="1 1 1"/>
      </geometry>
      <material name="light_black"/>
    </visual>
    <!-- <gravity>1</gravity>
    <velocity_decay/>
    <self_collide>0</self_collide> -->
  </link>

  <joint name='rotor_2_joint' type='revolute'>
    <parent link="base_link"/>
    <child link="rotor_2"/>      
    <axis xyz="0 0 1"/>
    
    <limit effort="0" velocity="0" lower="-1e+16" upper="1e+16"/>
    <dynamics damping="0.004"/>
    <use_parent_model_frame>1</use_parent_model_frame>
    <!-- </axis>
    <physics>
      <ode>
        <implicit_spring_damper>1</implicit_spring_damper>
      </ode>
    </physics> -->
  </joint>

  <link name='rotor_2'>
    <inertial>
      <origin xyz="0 0 0" rpy="0 -0 0" />
      <mass value="0.025"/>
      <inertia ixx="9.75e-06" ixy="0" ixz="0" iyy="0.000166704" iyz="0" izz="0.000167604"/>
    </inertial>

    <collision name='rotor_2_collision'>
      <origin xyz="0 0 0" rpy="0 -0 0"/>
      <geometry>
        <cylinder length="0.005" radius="0.1"/>
      </geometry>
      <!-- <surface>
        <contact>
          <ode/>
        </contact>
        <friction>
          <ode/>
        </friction>
      </surface> -->
    </collision>
    
    <visual name='rotor_2_visual'>
      <origin xyz="0.13 0.22 0.223" rpy="0 -0 0"/>
      <geometry>
        <mesh filename="package://uav_gazebo/models/iris_sensors/meshes/iris_prop_cw.dae" scale="1 1 1"/>
      </geometry>
      <material name="light_black"/>
    </visual>
    <!-- <gravity>1</gravity>
    <velocity_decay/>
    <self_collide>0</self_collide> -->
  </link>

  <joint name='rotor_3_joint' type='revolute'>
    <parent link="base_link" />
    <child link="rotor_3"/>
    <axis xyz="0 0 1"/>
    
    <limit effort="0" velocity="0" lower="-1e+16" upper="1e+16"/>
    <dynamics damping="0.004"/>  
    <use_parent_model_frame>1</use_parent_model_frame>
    <!-- </axis>
    <physics>
      <ode>
        <implicit_spring_damper>1</implicit_spring_damper>
      </ode>
    </physics> -->
  </joint>

  <link name='rotor_3'>
    <inertial>
      <origin xyz="0 0 0" rpy="0 -0 0"/>
      <mass value="0.025"/>
      <inertia ixx="9.75e-06" ixy="0" ixz="0" iyy="0.000166704" iyz="0" izz="0.000167604"/>
    </inertial>

    <collision name='rotor_3_collision'>
      <origin xyz="0 0 0" rpy="0 -0 0"/>
      <geometry>
        <cylinder length="0.005" radius="0.1"/>
      </geometry>
      <!-- <surface>
        <contact>
          <ode/>
        </contact>
        <friction>
          <ode/>
        </friction>
      </surface> -->
    </collision>

    <visual name='rotor_3_visual'>
      <origin xyz="-0.13 -0.2 0.223" rpy="0 -0 0"/>
      <geometry>
        <mesh filename="package://uav_gazebo/models/iris_sensors/meshes/iris_prop_cw.dae" scale="1 1 1"/>
      </geometry>
      <material name="light_black"/>
    </visual>
    <!-- <gravity>1</gravity>
    <velocity_decay/>
    <self_collide>0</self_collide> -->
  </link>

  <!-- <static>0</static> -->

</robot>